Workbook

Sheet Agent Registry
A1: LitigationOS Agent Fleet Operations
A2: 155+ Agents | 5 Fleets | 7 Tiers
A4: Agent ID | B4: Fleet | C4: Tier | D4: Agent Name | E4: Role | F4: Status | G4: Success Rate % | H4: Last Run | I4: Error Count | J4: Notes
A5: ▸ Delta9 Core Pipeline — 56 Agents (Tiers 1/2/3/J/K/L)
A6: A01 | B6: Delta9 | C6: 1 (I/O) | D6: File Indexer | E6: Scans all drives for new files | F6: OPERATIONAL | G6: 95.5 | H6: 45850.344 | I6: 5
A7: A02 | B7: Delta9 | C7: 1 (I/O) | D7: Deduplicator | E7: Content-based dedup across 6 drives | F7: OPERATIONAL | G7: 95.7 | H7: 45840.908 | I7: 1
A8: A03 | B8: Delta9 | C8: 1 (I/O) | D8: Classifier | E8: MEEK signal lane assignment | F8: OPERATIONAL | G8: 95.4 | H8: 45845.042 | I8: 4
A9: A04 | B9: Delta9 | C9: 1 (I/O) | D9: PDF Extractor | E9: PyMuPDF text/image extraction | F9: OPERATIONAL | G9: 96.1 | H9: 45847.792 | I9: 0
A10: A05 | B10: Delta9 | C10: 1 (I/O) | D10: DOCX Extractor | E10: python-docx structured extraction | F10: OPERATIONAL | G10: 96 | H10: 45849.94 | I10: 4
A11: A06 | B11: Delta9 | C11: 1 (I/O) | D11: Structured Extractor | E11: CSV/JSON/XML parsing | F11: OPERATIONAL | G11: 96.1 | H11: 45848.369 | I11: 3
A12: A07 | B12: Delta9 | C12: 1 (I/O) | D12: Atomizer | E12: Document → atomic evidence units | F12: OPERATIONAL | G12: 98.7 | H12: 45841.935 | I12: 0
A13: A08 | B13: Delta9 | C13: 1 (I/O) | D13: Archive Unpacker | E13: ZIP/RAR/7z recursive unpack | F13: OPERATIONAL | G13: 96.4 | H13: 45842.421 | I13: 2
A14: A09 | B14: Delta9 | C14: 1 (I/O) | D14: OCR Processor | E14: Tesseract OCR for scanned docs | F14: OPERATIONAL | G14: 96.9 | H14: 45844.485 | I14: 0
A15: A10 | B15: Delta9 | C15: 1 (I/O) | D15: Image Analyzer | E15: Image metadata + classification | F15: OPERATIONAL | G15: 99 | H15: 45850.607 | I15: 2
A16: A11 | B16: Delta9 | C16: 1 (I/O) | D16: Email Parser | E16: EML/MSG/MBOX parsing | F16: OPERATIONAL | G16: 99.8 | H16: 45845.108 | I16: 0
A17: A12 | B17: Delta9 | C17: 1 (I/O) | D17: Metadata Enricher | E17: Enriches file metadata | F17: OPERATIONAL | G17: 99.1 | H17: 45848.483 | I17: 2
... A43: L08 | B43: Delta9 | C43: L (Legal) | D43: Impeachment Builder | E43: Witness impeachment builder | F43: OPERATIONAL | G43: 96.2 | H43: 45848.087 | I43: 0
A44: ▸ Convergence Fleet — 6 Agents (F01-F06)
A45: F01 | B45: Convergence | C45: F (Convergence) | D45: Filing Assembly | E45: Cross-lane filing assembly | F45: OPERATIONAL | G45: 97.4 | H45: 45840.742 | I45: 2
A46: F02 | B46: Convergence | C46: F (Convergence) | D46: Brain Feed | E46: LEXOS brain feed generation | F46: OPERATIONAL | G46: 95.6 | H46: 45846.715 | I46: 0
A47: F03 | B47: Convergence | C47: F (Convergence) | D47: Graph Build | E47: Knowledge graph construction | F47: OPERATIONAL | G47: 97.6 | H47: 45848.551 | I47: 1
A48: F04 | B48: Convergence | C48: F (Convergence) | D48: Certification | E48: Filing certification + signing | F48: OPERATIONAL | G48: 98.7 | H48: 45850.281 | I48: 2
A49: F05 | B49: Convergence | C49: F (Convergence) | D49: Cross-Lane Sync | E49: Lane synchronization engine | F49: OPERATIONAL | G49: 97 | H49: 45849.849 | I49: 1
A50: F06 | B50: Convergence | C50: F (Convergence) | D50: Export | E50: CyclePack graph export | F50: OPERATIONAL | G50: 99.4 | H50: 45846.135 | I50: 1
A51: ▸ Delta999 Advanced Engines — 12 Agents
A52: D999-01 | B52: Delta999 | C52: D999 (Advanced) | D52: Classifier | E52: Advanced ML classification | F52: OPERATIONAL | G52: 95.1 | H52: 45847.317 | I52: 2
A53: D999-02 | B53: Delta999 | C53: D999 (Advanced) | D53: Validator | E53: Multi-stage validation engine | F53: OPERATIONAL | G53: 98.5 | H53: 45839.294 | I53: 0
A54: D999-03 | B54: Delta999 | C54: D999 (Advanced) | D54: Brief Engine | E54: Automated brief drafting | F54: OPERATIONAL | G54: 96.6 | H54: 45847.303 | I54: 6
A55: D999-04 | B55: Delta999 | C55: D999 (Advanced) | D55: Opposing Engine | E55: Counter-argument generation | F55: OPERATIONAL | G55: 97.6 | H55: 45850.775 | I55: 1
A56: D999-05 | B56: Delta999 | C56: D999 (Advanced) | D56: Settlement Engine | E56: Settlement strategy engine | F56: OPERATIONAL | G56: 97.3 | H56: 45845.254 | I56: 6
A57: D999-06 | B57: Delta999 | C57: D999 (Advanced) | D57: Assembly Engine | E57: Multi-document assembly | F57: DEGRADED | G57: 85.3 | H57: 45845.622 | I57: 3
A58: D999-07 | B58: Delta999 | C58: D999 (Advanced) | D58: Deadline Engine | E58: Deadline tracking + alerts | F58: OPERATIONAL | G58: 98.2 | H58: 45849.127 | I58: 5
A59: D999-08 | B59: Delta999 | C59: D999 (Advanced) | D59: DB Lock Manager | E59: SQLite WAL lock management | F59: OPERATIONAL | G59: 98.9 | H59: 45840.3 | I59: 2
A60: D999-09 | B60: Delta999 | C60: D999 (Advanced) | D60: Filing State Machine | E60: Filing workflow FSM | F60: OPERATIONAL | G60: 95.7 | H60: 45841.353 | I60: 3
A61: D999-10 | B61: Delta999 | C61: D999 (Advanced) | D61: Quality Gate | E61: Quality gate enforcement | F61: OPERATIONAL | G61: 97.2 | H61: 45852.713 | I61: 0
A62: D999-11 | B62: Delta999 | C62: D999 (Advanced) | D62: Evidence Gap Detector | E62: Evidence gap analysis | F62: DEGRADED | G62: 92.5 | H62: 45840.299 | I62: 4
A63: D999-12 | B63: Delta999 | C63: D999 (Advanced) | D63: Outcome Predictor | E63: Case outcome prediction | F63: OPERATIONAL | G63: 96 | H63: 45845.049 | I63: 3
A64: ▸ Copilot Agents — 64 Agents (10 shown)
A65: CP-01 | B65: Copilot | C65: Copilot | D65: michigan-litigation-orchestrator | E65: Multi-step filing workflows | F65: OPERATIONAL | G65: 95 | H65: 45845.374 | I65: 3
A66: CP-02 | B66: Copilot | C66: Copilot | D66: court-form-finder | E66: Michigan court form lookup | F66: OPERATIONAL | G66: 96.4 | H66: 45850.993 | I66: 3
...

Sheet Fleet Summary
A1: Fleet Summary — Aggregate Metrics
A2: All formulas reference Agent Registry sheet
A4: Fleet | B4: Total Agents | C4: Operational | D4: Degraded | E4: Offline | F4: Avg Success Rate % | G4: Total Runs | H4: Total Errors
A5: Delta9 | B5: =COUNTIF('Agent Registry'!$B$5:$B$80,A5) | C5: =COUNTIFS('Agent Registry'!$B$5:$B$80,A5,'Agent Registry'!$F$5:$F$80,"OPERATIONAL") | D5: =COUNTIFS('Agent Registry'!$B$5:$B$80,A5,'Agent Registry'!$F$5:$F$80,"DEGRADED") | E5: =COUNTIFS('Agent Registry'!$B$5:$B$80,A5,'Agent Registry'!$F$5:$F$80,"OFFLINE") | F5: =IFERROR(AVERAGEIF('Agent Registry'!$B$5:$B$80,A5,'Agent Registry'!$G$5:$G$80),0) | G5: 5040 | H5: =SUMIF('Agent Registry'!$B$5:$B$80,A5,'Agent Registry'!$I$5:$I$80)
A6: Convergence | B6: =COUNTIF('Agent Registry'!$B$5:$B$80,A6) | C6: =COUNTIFS('Agent Registry'!$B$5:$B$80,A6,'Agent Registry'!$F$5:$F$80,"OPERATIONAL") | D6: =COUNTIFS('Agent Registry'!$B$5:$B$80,A6,'Agent Registry'!$F$5:$F$80,"DEGRADED") | E6: =COUNTIFS('Agent Registry'!$B$5:$B$80,A6,'Agent Registry'!$F$5:$F$80,"OFFLINE") | F6: =IFERROR(AVERAGEIF('Agent Registry'!$B$5:$B$80,A6,'Agent Registry'!$G$5:$G$80),0) | G6: 972 | H6: =SUMIF('Agent Registry'!$B$5:$B$80,A6,'Agent Registry'!$I$5:$I$80)
A7: Delta999 | B7: =COUNTIF('Agent Registry'!$B$5:$B$80,A7) | C7: =COUNTIFS('Agent Registry'!$B$5:$B$80,A7,'Agent Registry'!$F$5:$F$80,"OPERATIONAL") | D7: =COUNTIFS('Agent Registry'!$B$5:$B$80,A7,'Agent Registry'!$F$5:$F$80,"DEGRADED") | E7: =COUNTIFS('Agent Registry'!$B$5:$B$80,A7,'Agent Registry'!$F$5:$F$80,"OFFLINE") | F7: =IFERROR(AVERAGEIF('Agent Registry'!$B$5:$B$80,A7,'Agent Registry'!$G$5:$G$80),0) | G7: 2268 | H7: =SUMIF('Agent Registry'!$B$5:$B$80,A7,'Agent Registry'!$I$5:$I$80)
A8: Copilot | B8: =COUNTIF('Agent Registry'!$B$5:$B$80,A8) | C8: =COUNTIFS('Agent Registry'!$B$5:$B$80,A8,'Agent Registry'!$F$5:$F$80,"OPERATIONAL") | D8: =COUNTIFS('Agent Registry'!$B$5:$B$80,A8,'Agent Registry'!$F$5:$F$80,"DEGRADED") | E8: =COUNTIFS('Agent Registry'!$B$5:$B$80,A8,'Agent Registry'!$F$5:$F$80,"OFFLINE") | F8: =IFERROR(AVERAGEIF('Agent Registry'!$B$5:$B$80,A8,'Agent Registry'!$G$5:$G$80),0) | G8: 8128 | H8: =SUMIF('Agent Registry'!$B$5:$B$80,A8,'Agent Registry'!$I$5:$I$80)
A9: Superpower | B9: =COUNTIF('Agent Registry'!$B$5:$B$80,A9) | C9: =COUNTIFS('Agent Registry'!$B$5:$B$80,A9,'Agent Registry'!$F$5:$F$80,"OPERATIONAL") | D9: =COUNTIFS('Agent Registry'!$B$5:$B$80,A9,'Agent Registry'!$F$5:$F$80,"DEGRADED") | E9: =COUNTIFS('Agent Registry'!$B$5:$B$80,A9,'Agent Registry'!$F$5:$F$80,"OFFLINE") | F9: =IFERROR(AVERAGEIF('Agent Registry'!$B$5:$B$80,A9,'Agent Registry'!$G$5:$G$80),0) | G9: 2405 | H9: =SUMIF('Agent Registry'!$B$5:$B$80,A9,'Agent Registry'!$I$5:$I$80)
A10: TOTAL | B10: =SUM(B5:B9) | C10: =SUM(C5:C9) | D10: =SUM(D5:D9) | E10: =SUM(E5:E9) | F10: =IFERROR(AVERAGE(F5:F9),0) | G10: =SUM(G5:G9) | H10: =SUM(H5:H9)
A13: Status Distribution (Chart Data)
A14: Status | B14: Count | C14: Percentage
A15: OPERATIONAL | B15: =COUNTIF('Agent Registry'!$F$5:$F$80,A15) | C15: =IFERROR(B15/SUM($B$15:$B$18)*100,0)
A16: DEGRADED | B16: =COUNTIF('Agent Registry'!$F$5:$F$80,A16) | C16: =IFERROR(B16/SUM($B$15:$B$18)*100,0)
A17: OFFLINE | B17: =COUNTIF('Agent Registry'!$F$5:$F$80,A17) | C17: =IFERROR(B17/SUM($B$15:$B$18)*100,0)
A18: UNTESTED | B18: =COUNTIF('Agent Registry'!$F$5:$F$80,A18) | C18: =IFERROR(B18/SUM($B$15:$B$18)*100,0)

Sheet Tier Performance
A1: Tier Performance Analysis
A2: Health Score = Success*0.4 + (100-ErrorRate)*0.3 + MIN(Throughput/100,100)*0.3
A4: Tier | B4: Agents | C4: Avg Success % | D4: Avg Runtime (s) | E4: Error Rate % | F4: Throughput (items/hr) | G4: Health Score | H4: Grade
A5: 1 (I/O) | B5: =COUNTIF('Agent Registry'!$C$5:$C$80,A5) | C5: =IFERROR(AVERAGEIF('Agent Registry'!$C$5:$C$80,A5,'Agent Registry'!$G$5:$G$80),0) | D5: 15.2 | E5: =IFERROR(SUMIF('Agent Registry'!$C$5:$C$80,A5,'Agent Registry'!$I$5:$I$80)/(B5*100)*100,0) | F5: 1250 | G5: =C5*0.4+(100-E5)*0.3+MIN(F5/100,100)*0.3 | H5: =IF(G5>=95,"A+",IF(G5>=90,"A",IF(G5>=85,"B+",IF(G5>=80,"B",IF(G5>=70,"C","D")))))
A6: 2 (Processing) | B6: =COUNTIF('Agent Registry'!$C$5:$C$80,A6) | C6: =IFERROR(AVERAGEIF('Agent Registry'!$C$5:$C$80,A6,'Agent Registry'!$G$5:$G$80),0) | D6: 22.7 | E6: =IFERROR(SUMIF('Agent Registry'!$C$5:$C$80,A6,'Agent Registry'!$I$5:$I$80)/(B6*100)*100,0) | F6: 800 | G6: =C6*0.4+(100-E6)*0.3+MIN(F6/100,100)*0.3 | H6: =IF(G6>=95,"A+",IF(G6>=90,"A",IF(G6>=85,"B+",IF(G6>=80,"B",IF(G6>=70,"C","D")))))
A7: 3 (Assembly) | B7: =COUNTIF('Agent Registry'!$C$5:$C$80,A7) | C7: =IFERROR(AVERAGEIF('Agent Registry'!$C$5:$C$80,A7,'Agent Registry'!$G$5:$G$80),0) | D7: 45.3 | E7: =IFERROR(SUMIF('Agent Registry'!$C$5:$C$80,A7,'Agent Registry'!$I$5:$I$80)/(B7*100)*100,0) | F7: 350 | G7: =C7*0.4+(100-E7)*0.3+MIN(F7/100,100)*0.3 | H7: =IF(G7>=95,"A+",IF(G7>=90,"A",IF(G7>=85,"B+",IF(G7>=80,"B",IF(G7>=70,"C","D")))))
A8: J (Judicial) | B8: =COUNTIF('Agent Registry'!$C$5:$C$80,A8) | C8: =IFERROR(AVERAGEIF('Agent Registry'!$C$5:$C$80,A8,'Agent Registry'!$G$5:$G$80),0) | D8: 38.1 | E8: =IFERROR(SUMIF('Agent Registry'!$C$5:$C$80,A8,'Agent Registry'!$I$5:$I$80)/(B8*100)*100,0) | F8: 420 | G8: =C8*0.4+(100-E8)*0.3+MIN(F8/100,100)*0.3 | H8: =IF(G8>=95,"A+",IF(G8>=90,"A",IF(G8>=85,"B+",IF(G8>=80,"B",IF(G8>=70,"C","D")))))
A9: K (Intel) | B9: =COUNTIF('Agent Registry'!$C$5:$C$80,A9) | C9: =IFERROR(AVERAGEIF('Agent Registry'!$C$5:$C$80,A9,'Agent Registry'!$G$5:$G$80),0) | D9: 31.5 | E9: =IFERROR(SUMIF('Agent Registry'!$C$5:$C$80,A9,'Agent Registry'!$I$5:$I$80)/(B9*100)*100,0) | F9: 550 | G9: =C9*0.4+(100-E9)*0.3+MIN(F9/100,100)*0.3 | H9: =IF(G9>=95,"A+",IF(G9>=90,"A",IF(G9>=85,"B+",IF(G9>=80,"B",IF(G9>=70,"C","D")))))
A10: L (Legal) | B10: =COUNTIF('Agent Registry'!$C$5:$C$80,A10) | C10: =IFERROR(AVERAGEIF('Agent Registry'!$C$5:$C$80,A10,'Agent Registry'!$G$5:$G$80),0) | D10: 28.9 | E10: =IFERROR(SUMIF('Agent Registry'!$C$5:$C$80,A10,'Agent Registry'!$I$5:$I$80)/(B10*100)*100,0) | F10: 630 | G10: =C10*0.4+(100-E10)*0.3+MIN(F10/100,100)*0.3 | H10: =IF(G10>=95,"A+",IF(G10>=90,"A",IF(G10>=85,"B+",IF(G10>=80,"B",IF(G10>=70,"C","D")))))
A11: F (Convergence) | B11: =COUNTIF('Agent Registry'!$C$5:$C$80,A11) | C11: =IFERROR(AVERAGEIF('Agent Registry'!$C$5:$C$80,A11,'Agent Registry'!$G$5:$G$80),0) | D11: 52 | E11: =IFERROR(SUMIF('Agent Registry'!$C$5:$C$80,A11,'Agent Registry'!$I$5:$I$80)/(B11*100)*100,0) | F11: 280 | G11: =C11*0.4+(100-E11)*0.3+MIN(F11/100,100)*0.3 | H11: =IF(G11>=95,"A+",IF(G11>=90,"A",IF(G11>=85,"B+",IF(G11>=80,"B",IF(G11>=70,"C","D")))))
A12: D999 (Advanced) | B12: =COUNTIF('Agent Registry'!$C$5:$C$80,A12) | C12: =IFERROR(AVERAGEIF('Agent Registry'!$C$5:$C$80,A12,'Agent Registry'!$G$5:$G$80),0) | D12: 19.8 | E12: =IFERROR(SUMIF('Agent Registry'!$C$5:$C$80,A12,'Agent Registry'!$I$5:$I$80)/(B12*100)*100,0) | F12: 900 | G12: =C12*0.4+(100-E12)*0.3+MIN(F12/100,100)*0.3 | H12: =IF(G12>=95,"A+",IF(G12>=90,"A",IF(G12>=85,"B+",IF(G12>=80,"B",IF(G12>=70,"C","D")))))
A13: Copilot | B13: =COUNTIF('Agent Registry'!$C$5:$C$80,A13) | C13: =IFERROR(AVERAGEIF('Agent Registry'!$C$5:$C$80,A13,'Agent Registry'!$G$5:$G$80),0) | D13: 8.5 | E13: =IFERROR(SUMIF('Agent Registry'!$C$5:$C$80,A13,'Agent Registry'!$I$5:$I$80)/(B13*100)*100,0) | F13: 1500 | G13: =C13*0.4+(100-E13)*0.3+MIN(F13/100,100)*0.3 | H13: =IF(G13>=95,"A+",IF(G13>=90,"A",IF(G13>=85,"B+",IF(G13>=80,"B",IF(G13>=70,"C","D")))))
A14: Superpower | B14: =COUNTIF('Agent Registry'!$C$5:$C$80,A14) | C14: =IFERROR(AVERAGEIF('Agent Registry'!$C$5:$C$80,A14,'Agent Registry'!$G$5:$G$80),0) | D14: 12 | E14: =IFERROR(SUMIF('Agent Registry'!$C$5:$C$80,A14,'Agent Registry'!$I$5:$I$80)/(B14*100)*100,0) | F14: 1100 | G14: =C14*0.4+(100-E14)*0.3+MIN(F14/100,100)*0.3 | H14: =IF(G14>=95,"A+",IF(G14>=90,"A",IF(G14>=85,"B+",IF(G14>=80,"B",IF(G14>=70,"C","D")))))

Sheet Error Log
A1: Agent Error Log
A2: Track and resolve agent errors — sorted by severity
A4: Timestamp | B4: Agent ID | C4: Error Type | D4: Severity | E4: Message | F4: Resolution | G4: Retry Count | H4: Resolved?
A5: 45852.385 | B5: A02 | C5: SQLITE | D5: CRITICAL | E5: SQLITE_BUSY — database is locked after 60s timeout | F5: Increased busy_timeout to 180s; reduced concurrent connections | G5: 3 | H5: YES
A6: 45852.363 | B6: D999-08 | C6: PIPE | D6: CRITICAL | E6: write EAGAIN — pipe buffer overflow on stdout | F6: Reduced concurrent shells from 3→2; output capped at 100 lines | G6: 0 | H6: YES
A7: 45851.938 | B7: A09 | C7: IMPORT | D7: HIGH | E7: ImportError: No module named 'json' (shadow module in repo root) | F7: Set CWD to script directory; use safe_run() wrapper | G7: 1 | H7: YES
A8: 45851.67 | B8: F03 | C8: FILE | D8: HIGH | E8: FileNotFoundError: knowledge_graph.db not found on G:\ drive | F8: Added drive availability check before graph build phase | G8: 2 | H8: YES
A9: 45851.597 | B9: K02 | C9: TIMEOUT | D9: MEDIUM | E9: TimeoutError: Opposing strategy analysis exceeded 120s deadman switch | F9: Optimized query; added incremental processing with checkpoints | G9: 3 | H9: YES
A10: 45850.458 | B10: L04 | C10: DATA | D10: MEDIUM | E10: MCR rule index missing entries for MCR 2.003(D) amendments | F10: Rebuilt rule index from authoritative source; verified completeness | G10: 1 | H10: YES
A11: 45850.406 | B11: J01 | C11: PERMISSION | D11: MEDIUM | E11: PermissionError: Cannot write to judicial_findings table — WAL lock held | F11: Implemented retry with exponential backoff; max 3 retries | G11: 2 | H11: YES
A12: 45849.844 | B12: CP-03 | C12: MEMORY | D12: LOW | E12: MemoryWarning: preflight QA cache exceeded 512MB threshold | F12: Added LRU eviction policy; cache capped at 256MB | G12: 0 | H12: YES
A13: 45849.646 | B13: SP-03 | C13: UNKNOWN | D13: LOW | E13: Self-evolution cycle produced no improvements after 5 iterations | F13: Expanded training corpus; adjusted learning rate schedule | G13: 0 | H13: NO
A14: 45848.5 | B14: B03 | C14: DATA | D14: MEDIUM | E14: Timeline gap: 47-day hole in custody exchange records (Mar-Apr 2024) | F14: Created evidence acquisition task; flagged for manual review | G14: 0 | H14: NO
