Workbook

Sheet Authority Index
A1: Legal Authority Cross-Reference — Pigors v. All
A2: Master Index of 60 Key Authorities Across 6 Litigation Lanes
A4: ID | B4: Citation | C4: Short Name | D4: Type | E4: Jurisdiction | F4: Year | G4: Lane(s) | H4: Filings Used In | I4: Weight Score | J4: Chain Status | K4: Key Holding | L4: Notes
A5: 1 | B5: Troxel v. Granville, 530 U.S. 57 (2000) | C5: Troxel | D5: SCOTUS | E5: Federal | F5: 2000 | G5: A,E | H5: JTC,MSC Super,Contempt,Emergency PT | I5: 95 | J5: COMPLETE | K5: Parental rights are fundamental liberty interests | L5: Controlling on parental rights claims
A6: 2 | B6: Mathews v. Eldridge, 424 U.S. 319 (1976) | C6: Mathews | D6: SCOTUS | E6: Federal | F6: 1976 | G6: E | H6: JTC,MSC Super,Federal | I6: 90 | J6: COMPLETE | K6: Three-part due process balancing test | L6: Framework for all DP claims
A7: 3 | B7: Monell v. Dept. Social Services, 436 U.S. 658 (1978) | C7: Monell | D7: SCOTUS | E7: Federal | F7: 1978 | G7: E | H7: Federal | I7: 90 | J7: COMPLETE | K7: Municipal liability under §1983 requires policy/custom | L7: Basis for institutional claims
A8: 4 | B8: Santosky v. Kramer, 455 U.S. 745 (1982) | C8: Santosky | D8: SCOTUS | E8: Federal | F8: 1982 | G8: A | H8: Contempt,Emergency PT | I8: 85 | J8: STRONG | K8: Clear and convincing evidence standard for parental rights | L8: Heightened burden required
A9: 5 | B9: Stanley v. Illinois, 405 U.S. 645 (1972) | C9: Stanley | D9: SCOTUS | E9: Federal | F9: 1972 | G9: A | H9: Contempt,Emergency PT,JTC | I9: 85 | J9: COMPLETE | K9: Unwed fathers have protected parental rights | L9: Foundation for father's rights claims
A10: 6 | B10: Lassiter v. Dept. Social Services, 452 U.S. 18 (1981) | C10: Lassiter | D10: SCOTUS | E10: Federal | F10: 1981 | G10: A,E | H10: JTC,MSC Super | I10: 80 | J10: STRONG | K10: Due process may require counsel in custody proceedings | L10: Supports right-to-counsel argument
A11: 7 | B11: Turner v. Rogers, 564 U.S. 431 (2011) | C11: Turner | D11: SCOTUS | E11: Federal | F11: 2011 | G11: A,E | H11: JTC,MSC Super,Contempt | I11: 80 | J11: COMPLETE | K11: Procedural safeguards required for pro se litigants | L11: Key for pro se protection claims
A12: 8 | B12: Caperton v. Massey, 556 U.S. 868 (2009) | C12: Caperton | D12: SCOTUS | E12: Federal | F12: 2009 | G12: E | H12: JTC,Disqual | I12: 85 | J12: COMPLETE | K12: Due process requires recusal for probability of bias | L12: Strongest bias/disqual authority
A13: 9 | B13: Texas Dept. v. Leblanc, 137 S.Ct. 1098 (2017) | C13: Leblanc | D13: SCOTUS | E13: Federal | F13: 2017 | G13: E | H13: Federal | I13: 75 | J13: STRONG | K13: Clearly established right standard for §1983 | L13: Qualified immunity analysis
A14: 10 | B14: Heck v. Humphrey, 512 U.S. 477 (1994) | C14: Heck | D14: SCOTUS | E14: Federal | F14: 1994 | G14: E | H14: Federal | I14: 70 | J14: GAPS | K14: §1983 requires favorable termination of underlying proceeding | L14: May limit timing of federal suit
A15: 11 | B15: Vodvarka v. Grasmeyer, 259 Mich App 499 (2003) | C15: Vodvarka | D15: MI_COA | E15: Michigan | F15: 2003 | G15: A | H15: Contempt,Emergency PT,COA Brief | I15: 95 | J15: COMPLETE | K15: Proper cause/change of circumstances threshold for custody modification | L15: Controlling standard Lane A
A16: 12 | B16: Pierron v. Pierron, 486 Mich 81 (2010) | C16: Pierron | D16: MI_SC | E16: Michigan | F16: 2010 | G16: A | H16: Contempt,Emergency PT,COA Brief | I16: 90 | J16: COMPLETE | K16: Best interest factors must be individually analyzed | L16: Binding on all MI courts
... A64: 60 | B64: Widgren v. Maple Grove Twp., 429 F.3d 575 (6th Cir. 2005) | C64: Widgren | D64: 6TH_CIR | E64: Federal | F64: 2005 | G64: B | H64: Housing,Federal | I64: 80 | J64: COMPLETE | K64: Fair housing zoning discrimination analysis | L64: FHA enforcement standard
A66: TOTALS | H66: Count: | I66: =COUNTA(I5:I64)
H67: Average Weight: | I67: =AVERAGE(I5:I64)
H68: COMPLETE chains: | I68: =COUNTIF(J5:J64,"COMPLETE")
H69: GAPS chains: | I69: =COUNTIF(J5:J64,"GAPS")

Sheet Lane Assignment Matrix
A1: Authority × Lane Assignment Matrix
A3: ID | B3: Short Name | C3: Lane A (Custody (Watson)) | D3: Lane B (Housing (Shady Oaks)) | E3: Lane C (Convergence) | F3: Lane D (PPO) | G3: Lane E (Judicial Misconduct) | H3: Lane F (Appellate)
A4: ='Authority Index'!A5 | B4: ='Authority Index'!C5 | C4: X | G4: X
A5: ='Authority Index'!A6 | B5: ='Authority Index'!C6 | G5: X
A6: ='Authority Index'!A7 | B6: ='Authority Index'!C7 | G6: X
A7: ='Authority Index'!A8 | B7: ='Authority Index'!C8 | C7: X
A8: ='Authority Index'!A9 | B8: ='Authority Index'!C9 | C8: X
A9: ='Authority Index'!A10 | B9: ='Authority Index'!C10 | C9: X | G9: X
A10: ='Authority Index'!A11 | B10: ='Authority Index'!C11 | C10: X | G10: X
A11: ='Authority Index'!A12 | B11: ='Authority Index'!C12 | G11: X
A12: ='Authority Index'!A13 | B12: ='Authority Index'!C13 | G12: X
A13: ='Authority Index'!A14 | B13: ='Authority Index'!C14 | G13: X
A14: ='Authority Index'!A15 | B14: ='Authority Index'!C15 | C14: X
A15: ='Authority Index'!A16 | B15: ='Authority Index'!C16 | C15: X
A16: ='Authority Index'!A17 | B16: ='Authority Index'!C17 | C16: X
A17: ='Authority Index'!A18 | B17: ='Authority Index'!C18 | C17: X
A18: ='Authority Index'!A19 | B18: ='Authority Index'!C19 | C18: X
A19: ='Authority Index'!A20 | B19: ='Authority Index'!C20 | C19: X
A20: ='Authority Index'!A21 | B20: ='Authority Index'!C21 | C20: X
A21: ='Authority Index'!A22 | B21: ='Authority Index'!C22 | C21: X
A22: ='Authority Index'!A23 | B22: ='Authority Index'!C23 | D22: X
A23: ='Authority Index'!A24 | B23: ='Authority Index'!C24 | D23: X
A24: ='Authority Index'!A25 | B24: ='Authority Index'!C25 | D24: X
A25: ='Authority Index'!A26 | B25: ='Authority Index'!C26 | D25: X
A26: ='Authority Index'!A27 | B26: ='Authority Index'!C27 | D26: X
A27: ='Authority Index'!A28 | B27: ='Authority Index'!C28 | D27: X
A28: ='Authority Index'!A29 | B28: ='Authority Index'!C29 | C28: X | D28: X | G28: X
A29: ='Authority Index'!A30 | B29: ='Authority Index'!C30 | G29: X
A30: ='Authority Index'!A31 | B30: ='Authority Index'!C31 | C30: X | D30: X | F30: X
A31: ='Authority Index'!A32 | B31: ='Authority Index'!C32 | G31: X | H31: X
A32: ='Authority Index'!A33 | B32: ='Authority Index'!C33 | C32: X
A33: ='Authority Index'!A34 | B33: ='Authority Index'!C34 | C33: X
A34: ='Authority Index'!A35 | B34: ='Authority Index'!C35 | H34: X
A35: ='Authority Index'!A36 | B35: ='Authority Index'!C36 | H35: X
A36: ='Authority Index'!A37 | B36: ='Authority Index'!C37 | H36: X
A37: ='Authority Index'!A38 | B37: ='Authority Index'!C38 | G37: X
A38: ='Authority Index'!A39 | B38: ='Authority Index'!C39 | G38: X
A39: ='Authority Index'!A40 | B39: ='Authority Index'!C40 | G39: X
A40: ='Authority Index'!A41 | B40: ='Authority Index'!C41 | C40: X | D40: X
A41: ='Authority Index'!A42 | B41: ='Authority Index'!C42 | C41: X | D41: X
...

Sheet Filing Cross-Reference
A1: Authority × Filing Cross-Reference Matrix
A3: ID | B3: Short Name | C3: JTC | D3: MSC Super | E3: Contempt | F3: Disqual | G3: Emergency PT | H3: COA Brief | I3: Housing | J3: Federal | K3: Tort | L3: Citations/Authority
A4: ='Authority Index'!A5 | B4: ='Authority Index'!C5 | C4: X | D4: X | E4: X | G4: X | L4: =COUNTIF(C4:K4,"X")
A5: ='Authority Index'!A6 | B5: ='Authority Index'!C6 | C5: X | D5: X | J5: X | L5: =COUNTIF(C5:K5,"X")
A6: ='Authority Index'!A7 | B6: ='Authority Index'!C7 | J6: X | L6: =COUNTIF(C6:K6,"X")
A7: ='Authority Index'!A8 | B7: ='Authority Index'!C8 | E7: X | G7: X | L7: =COUNTIF(C7:K7,"X")
A8: ='Authority Index'!A9 | B8: ='Authority Index'!C9 | C8: X | E8: X | G8: X | L8: =COUNTIF(C8:K8,"X")
A9: ='Authority Index'!A10 | B9: ='Authority Index'!C10 | C9: X | D9: X | L9: =COUNTIF(C9:K9,"X")
A10: ='Authority Index'!A11 | B10: ='Authority Index'!C11 | C10: X | D10: X | E10: X | L10: =COUNTIF(C10:K10,"X")
A11: ='Authority Index'!A12 | B11: ='Authority Index'!C12 | C11: X | F11: X | L11: =COUNTIF(C11:K11,"X")
A12: ='Authority Index'!A13 | B12: ='Authority Index'!C13 | J12: X | L12: =COUNTIF(C12:K12,"X")
A13: ='Authority Index'!A14 | B13: ='Authority Index'!C14 | J13: X | L13: =COUNTIF(C13:K13,"X")
A14: ='Authority Index'!A15 | B14: ='Authority Index'!C15 | E14: X | G14: X | H14: X | L14: =COUNTIF(C14:K14,"X")
A15: ='Authority Index'!A16 | B15: ='Authority Index'!C16 | E15: X | G15: X | H15: X | L15: =COUNTIF(C15:K15,"X")
A16: ='Authority Index'!A17 | B16: ='Authority Index'!C17 | E16: X | G16: X | H16: X | L16: =COUNTIF(C16:K16,"X")
A17: ='Authority Index'!A18 | B17: ='Authority Index'!C18 | E17: X | H17: X | L17: =COUNTIF(C17:K17,"X")
A18: ='Authority Index'!A19 | B18: ='Authority Index'!C19 | G18: X | H18: X | L18: =COUNTIF(C18:K18,"X")
A19: ='Authority Index'!A20 | B19: ='Authority Index'!C20 | E19: X | F19: X | G19: X | H19: X | L19: =COUNTIF(C19:K19,"X")
A20: ='Authority Index'!A21 | B20: ='Authority Index'!C21 | E20: X | G20: X | H20: X | L20: =COUNTIF(C20:K20,"X")
A21: ='Authority Index'!A22 | B21: ='Authority Index'!C22 | E21: X | L21: =COUNTIF(C21:K21,"X")
A22: ='Authority Index'!A23 | B22: ='Authority Index'!C23 | I22: X | K22: X | L22: =COUNTIF(C22:K22,"X")
A23: ='Authority Index'!A24 | B23: ='Authority Index'!C24 | I23: X | K23: X | L23: =COUNTIF(C23:K23,"X")
A24: ='Authority Index'!A25 | B24: ='Authority Index'!C25 | I24: X | L24: =COUNTIF(C24:K24,"X")
A25: ='Authority Index'!A26 | B25: ='Authority Index'!C26 | I25: X | K25: X | L25: =COUNTIF(C25:K25,"X")
A26: ='Authority Index'!A27 | B26: ='Authority Index'!C27 | I26: X | L26: =COUNTIF(C26:K26,"X")
A27: ='Authority Index'!A28 | B27: ='Authority Index'!C28 | I27: X | L27: =COUNTIF(C27:K27,"X")
A28: ='Authority Index'!A29 | B28: ='Authority Index'!C29 | I28: X | J28: X | K28: X | L28: =COUNTIF(C28:K28,"X")
A29: ='Authority Index'!A30 | B29: ='Authority Index'!C30 | C29: X | D29: X | F29: X | L29: =COUNTIF(C29:K29,"X")
A30: ='Authority Index'!A31 | B30: ='Authority Index'!C31 | E30: X | F30: X | G30: X | I30: X | L30: =COUNTIF(C30:K30,"X")
A31: ='Authority Index'!A32 | B31: ='Authority Index'!C32 | D31: X | H31: X | L31: =COUNTIF(C31:K31,"X")
A32: ='Authority Index'!A33 | B32: ='Authority Index'!C33 | E32: X | G32: X | L32: =COUNTIF(C32:K32,"X")
A33: ='Authority Index'!A34 | B33: ='Authority Index'!C34 | E33: X | G33: X | L33: =COUNTIF(C33:K33,"X")
A34: ='Authority Index'!A35 | B34: ='Authority Index'!C35 | H34: X | L34: =COUNTIF(C34:K34,"X")
A35: ='Authority Index'!A36 | B35: ='Authority Index'!C36 | H35: X | L35: =COUNTIF(C35:K35,"X")
A36: ='Authority Index'!A37 | B36: ='Authority Index'!C37 | H36: X | L36: =COUNTIF(C36:K36,"X")
A37: ='Authority Index'!A38 | B37: ='Authority Index'!C38 | D37: X | L37: =COUNTIF(C37:K37,"X")
A38: ='Authority Index'!A39 | B38: ='Authority Index'!C39 | D38: X | L38: =COUNTIF(C38:K38,"X")
A39: ='Authority Index'!A40 | B39: ='Authority Index'!C40 | C39: X | D39: X | L39: =COUNTIF(C39:K39,"X")
A40: ='Authority Index'!A41 | B40: ='Authority Index'!C41 | E40: X | I40: X | L40: =COUNTIF(C40:K40,"X")
A41: ='Authority Index'!A42 | B41: ='Authority Index'!C42 | E41: X | I41: X | L41: =COUNTIF(C41:K41,"X")
...

Sheet Authority Chain Completeness
A1: Authority Chain Completeness Tracker
A3: Chain ID | B3: Vehicle / Filing | C3: Required Authorities | D3: Found | E3: Missing | F3: Completeness % | G3: Status
A4: CH-01 | B4: JTC Complaint — Due Process | C4: 8 | D4: 7 | E4: =C4-D4 | F4: =IF(C4>0,D4/C4,0) | G4: =IF(F4=1,"COMPLETE",IF(F4>=0.75,"STRONG","GAPS"))
A5: CH-02 | B5: JTC Complaint — Bias Pattern | C5: 6 | D5: 6 | E5: =C5-D5 | F5: =IF(C5>0,D5/C5,0) | G5: =IF(F5=1,"COMPLETE",IF(F5>=0.75,"STRONG","GAPS"))
A6: CH-03 | B6: JTC Complaint — Parental Rights | C6: 7 | D6: 6 | E6: =C6-D6 | F6: =IF(C6>0,D6/C6,0) | G6: =IF(F6=1,"COMPLETE",IF(F6>=0.75,"STRONG","GAPS"))
A7: CH-04 | B7: MSC Superintending Control | C7: 9 | D7: 9 | E7: =C7-D7 | F7: =IF(C7>0,D7/C7,0) | G7: =IF(F7=1,"COMPLETE",IF(F7>=0.75,"STRONG","GAPS"))
A8: CH-05 | B8: MSC Emergency Application | C8: 6 | D8: 5 | E8: =C8-D8 | F8: =IF(C8>0,D8/C8,0) | G8: =IF(F8=1,"COMPLETE",IF(F8>=0.75,"STRONG","GAPS"))
A9: CH-06 | B9: Contempt Motion — PT Denial | C9: 8 | D9: 8 | E9: =C9-D9 | F9: =IF(C9>0,D9/C9,0) | G9: =IF(F9=1,"COMPLETE",IF(F9>=0.75,"STRONG","GAPS"))
A10: CH-07 | B10: Contempt Motion — Order Violation | C10: 6 | D10: 6 | E10: =C10-D10 | F10: =IF(C10>0,D10/C10,0) | G10: =IF(F10=1,"COMPLETE",IF(F10>=0.75,"STRONG","GAPS"))
A11: CH-08 | B11: Disqualification Motion | C11: 5 | D11: 5 | E11: =C11-D11 | F11: =IF(C11>0,D11/C11,0) | G11: =IF(F11=1,"COMPLETE",IF(F11>=0.75,"STRONG","GAPS"))
A12: CH-09 | B12: Emergency PT Motion | C12: 10 | D12: 9 | E12: =C12-D12 | F12: =IF(C12>0,D12/C12,0) | G12: =IF(F12=1,"COMPLETE",IF(F12>=0.75,"STRONG","GAPS"))
A13: CH-10 | B13: COA Brief — Custody Mod | C13: 12 | D13: 11 | E13: =C13-D13 | F13: =IF(C13>0,D13/C13,0) | G13: =IF(F13=1,"COMPLETE",IF(F13>=0.75,"STRONG","GAPS"))
A14: CH-11 | B14: COA Brief — Procedure | C14: 8 | D14: 8 | E14: =C14-D14 | F14: =IF(C14>0,D14/C14,0) | G14: =IF(F14=1,"COMPLETE",IF(F14>=0.75,"STRONG","GAPS"))
A15: CH-12 | B15: COA Brief — Constitutional | C15: 7 | D15: 7 | E15: =C15-D15 | F15: =IF(C15>0,D15/C15,0) | G15: =IF(F15=1,"COMPLETE",IF(F15>=0.75,"STRONG","GAPS"))
... A31: CH-28 | B31: Void Judgment Challenge | C31: 5 | D31: 5 | E31: =C31-D31 | F31: =IF(C31>0,D31/C31,0) | G31: =IF(F31=1,"COMPLETE",IF(F31>=0.75,"STRONG","GAPS"))
A33: SUMMARY
B34: Total Chains: | C34: =COUNTA(A4:A31)
B35: COMPLETE: | C35: =COUNTIF(G4:G31,"COMPLETE")
B36: STRONG: | C36: =COUNTIF(G4:G31,"STRONG")
B37: GAPS: | C37: =COUNTIF(G4:G31,"GAPS")
B38: Avg Completeness: | C38: =AVERAGE(F4:F31)
B39: Total Required: | C39: =SUM(C4:C31)
B40: Total Found: | C40: =SUM(D4:D31)
B41: Total Missing: | C41: =SUM(E4:E31)

Sheet Weight Analysis
A1: Authority Weight & Coverage Analysis
A3: SECTION A: Average Weight by Authority Type
A4: Authority Type | B4: Count | C4: Avg Weight | D4: Max Weight
A5: SCOTUS | B5: =COUNTIF('Authority Index'!D$5:D$64,"SCOTUS") | C5: =IFERROR(AVERAGEIF('Authority Index'!D$5:D$64,"SCOTUS",'Authority Index'!I$5:I$64),0) | D5: =IFERROR(MAXIFS('Authority Index'!I$5:I$64,'Authority Index'!D$5:D$64,"SCOTUS"),0)
A6: MI_SC | B6: =COUNTIF('Authority Index'!D$5:D$64,"MI_SC") | C6: =IFERROR(AVERAGEIF('Authority Index'!D$5:D$64,"MI_SC",'Authority Index'!I$5:I$64),0) | D6: =IFERROR(MAXIFS('Authority Index'!I$5:I$64,'Authority Index'!D$5:D$64,"MI_SC"),0)
A7: MI_COA | B7: =COUNTIF('Authority Index'!D$5:D$64,"MI_COA") | C7: =IFERROR(AVERAGEIF('Authority Index'!D$5:D$64,"MI_COA",'Authority Index'!I$5:I$64),0) | D7: =IFERROR(MAXIFS('Authority Index'!I$5:I$64,'Authority Index'!D$5:D$64,"MI_COA"),0)
A8: MCR | B8: =COUNTIF('Authority Index'!D$5:D$64,"MCR") | C8: =IFERROR(AVERAGEIF('Authority Index'!D$5:D$64,"MCR",'Authority Index'!I$5:I$64),0) | D8: =IFERROR(MAXIFS('Authority Index'!I$5:I$64,'Authority Index'!D$5:D$64,"MCR"),0)
A9: MCL | B9: =COUNTIF('Authority Index'!D$5:D$64,"MCL") | C9: =IFERROR(AVERAGEIF('Authority Index'!D$5:D$64,"MCL",'Authority Index'!I$5:I$64),0) | D9: =IFERROR(MAXIFS('Authority Index'!I$5:I$64,'Authority Index'!D$5:D$64,"MCL"),0)
A10: FED_STAT | B10: =COUNTIF('Authority Index'!D$5:D$64,"FED_STAT") | C10: =IFERROR(AVERAGEIF('Authority Index'!D$5:D$64,"FED_STAT",'Authority Index'!I$5:I$64),0) | D10: =IFERROR(MAXIFS('Authority Index'!I$5:I$64,'Authority Index'!D$5:D$64,"FED_STAT"),0)
A11: FED_RULE | B11: =COUNTIF('Authority Index'!D$5:D$64,"FED_RULE") | C11: =IFERROR(AVERAGEIF('Authority Index'!D$5:D$64,"FED_RULE",'Authority Index'!I$5:I$64),0) | D11: =IFERROR(MAXIFS('Authority Index'!I$5:I$64,'Authority Index'!D$5:D$64,"FED_RULE"),0)
A12: CONST | B12: =COUNTIF('Authority Index'!D$5:D$64,"CONST") | C12: =IFERROR(AVERAGEIF('Authority Index'!D$5:D$64,"CONST",'Authority Index'!I$5:I$64),0) | D12: =IFERROR(MAXIFS('Authority Index'!I$5:I$64,'Authority Index'!D$5:D$64,"CONST"),0)
A13: 6TH_CIR | B13: =COUNTIF('Authority Index'!D$5:D$64,"6TH_CIR") | C13: =IFERROR(AVERAGEIF('Authority Index'!D$5:D$64,"6TH_CIR",'Authority Index'!I$5:I$64),0) | D13: =IFERROR(MAXIFS('Authority Index'!I$5:I$64,'Authority Index'!D$5:D$64,"6TH_CIR"),0)
A16: SECTION B: Top 10 Strongest Authorities (by Weight)
A17: Rank | B17: Weight | C17: Citation | D17: Type | E17: Lane(s)
A18: 1 | B18: =LARGE('Authority Index'!I$5:I$64,1) | C18: =IFERROR(INDEX('Authority Index'!B$5:B$64,MATCH(LARGE('Authority Index'!I$5:I$64,1),'Authority Index'!I$5:I$64,0)),"") | D18: =IFERROR(INDEX('Authority Index'!D$5:D$64,MATCH(LARGE('Authority Index'!I$5:I$64,1),'Authority Index'!I$5:I$64,0)),"") | E18: =IFERROR(INDEX('Authority Index'!G$5:G$64,MATCH(LARGE('Authority Index'!I$5:I$64,1),'Authority Index'!I$5:I$64,0)),"")
A19: 2 | B19: =LARGE('Authority Index'!I$5:I$64,2) | C19: =IFERROR(INDEX('Authority Index'!B$5:B$64,MATCH(LARGE('Authority Index'!I$5:I$64,2),'Authority Index'!I$5:I$64,0)),"") | D19: =IFERROR(INDEX('Authority Index'!D$5:D$64,MATCH(LARGE('Authority Index'!I$5:I$64,2),'Authority Index'!I$5:I$64,0)),"") | E19: =IFERROR(INDEX('Authority Index'!G$5:G$64,MATCH(LARGE('Authority Index'!I$5:I$64,2),'Authority Index'!I$5:I$64,0)),"")
A20: 3 | B20: =LARGE('Authority Index'!I$5:I$64,3) | C20: =IFERROR(INDEX('Authority Index'!B$5:B$64,MATCH(LARGE('Authority Index'!I$5:I$64,3),'Authority Index'!I$5:I$64,0)),"") | D20: =IFERROR(INDEX('Authority Index'!D$5:D$64,MATCH(LARGE('Authority Index'!I$5:I$64,3),'Authority Index'!I$5:I$64,0)),"") | E20: =IFERROR(INDEX('Authority Index'!G$5:G$64,MATCH(LARGE('Authority Index'!I$5:I$64,3),'Authority Index'!I$5:I$64,0)),"")
A21: 4 | B21: =LARGE('Authority Index'!I$5:I$64,4) | C21: =IFERROR(INDEX('Authority Index'!B$5:B$64,MATCH(LARGE('Authority Index'!I$5:I$64,4),'Authority Index'!I$5:I$64,0)),"") | D21: =IFERROR(INDEX('Authority Index'!D$5:D$64,MATCH(LARGE('Authority Index'!I$5:I$64,4),'Authority Index'!I$5:I$64,0)),"") | E21: =IFERROR(INDEX('Authority Index'!G$5:G$64,MATCH(LARGE('Authority Index'!I$5:I$64,4),'Authority Index'!I$5:I$64,0)),"")
A22: 5 | B22: =LARGE('Authority Index'!I$5:I$64,5) | C22: =IFERROR(INDEX('Authority Index'!B$5:B$64,MATCH(LARGE('Authority Index'!I$5:I$64,5),'Authority Index'!I$5:I$64,0)),"") | D22: =IFERROR(INDEX('Authority Index'!D$5:D$64,MATCH(LARGE('Authority Index'!I$5:I$64,5),'Authority Index'!I$5:I$64,0)),"") | E22: =IFERROR(INDEX('Authority Index'!G$5:G$64,MATCH(LARGE('Authority Index'!I$5:I$64,5),'Authority Index'!I$5:I$64,0)),"")
A23: 6 | B23: =LARGE('Authority Index'!I$5:I$64,6) | C23: =IFERROR(INDEX('Authority Index'!B$5:B$64,MATCH(LARGE('Authority Index'!I$5:I$64,6),'Authority Index'!I$5:I$64,0)),"") | D23: =IFERROR(INDEX('Authority Index'!D$5:D$64,MATCH(LARGE('Authority Index'!I$5:I$64,6),'Authority Index'!I$5:I$64,0)),"") | E23: =IFERROR(INDEX('Authority Index'!G$5:G$64,MATCH(LARGE('Authority Index'!I$5:I$64,6),'Authority Index'!I$5:I$64,0)),"")
A24: 7 | B24: =LARGE('Authority Index'!I$5:I$64,7) | C24: =IFERROR(INDEX('Authority Index'!B$5:B$64,MATCH(LARGE('Authority Index'!I$5:I$64,7),'Authority Index'!I$5:I$64,0)),"") | D24: =IFERROR(INDEX('Authority Index'!D$5:D$64,MATCH(LARGE('Authority Index'!I$5:I$64,7),'Authority Index'!I$5:I$64,0)),"") | E24: =IFERROR(INDEX('Authority Index'!G$5:G$64,MATCH(LARGE('Authority Index'!I$5:I$64,7),'Authority Index'!I$5:I$64,0)),"")
A25: 8 | B25: =LARGE('Authority Index'!I$5:I$64,8) | C25: =IFERROR(INDEX('Authority Index'!B$5:B$64,MATCH(LARGE('Authority Index'!I$5:I$64,8),'Authority Index'!I$5:I$64,0)),"") | D25: =IFERROR(INDEX('Authority Index'!D$5:D$64,MATCH(LARGE('Authority Index'!I$5:I$64,8),'Authority Index'!I$5:I$64,0)),"") | E25: =IFERROR(INDEX('Authority Index'!G$5:G$64,MATCH(LARGE('Authority Index'!I$5:I$64,8),'Authority Index'!I$5:I$64,0)),"")
A26: 9 | B26: =LARGE('Authority Index'!I$5:I$64,9) | C26: =IFERROR(INDEX('Authority Index'!B$5:B$64,MATCH(LARGE('Authority Index'!I$5:I$64,9),'Authority Index'!I$5:I$64,0)),"") | D26: =IFERROR(INDEX('Authority Index'!D$5:D$64,MATCH(LARGE('Authority Index'!I$5:I$64,9),'Authority Index'!I$5:I$64,0)),"") | E26: =IFERROR(INDEX('Authority Index'!G$5:G$64,MATCH(LARGE('Authority Index'!I$5:I$64,9),'Authority Index'!I$5:I$64,0)),"")
A27: 10 | B27: =LARGE('Authority Index'!I$5:I$64,10) | C27: =IFERROR(INDEX('Authority Index'!B$5:B$64,MATCH(LARGE('Authority Index'!I$5:I$64,10),'Authority Index'!I$5:I$64,0)),"") | D27: =IFERROR(INDEX('Authority Index'!D$5:D$64,MATCH(LARGE('Authority Index'!I$5:I$64,10),'Authority Index'!I$5:I$64,0)),"") | E27: =IFERROR(INDEX('Authority Index'!G$5:G$64,MATCH(LARGE('Authority Index'!I$5:I$64,10),'Authority Index'!I$5:I$64,0)),"")
A30: SECTION C: Citation Count per Filing (Cross-Sheet)
A31: Filing | B31: Total Citations | C31: % of Total | D31: Strength
A32: JTC | B32: ='Filing Cross-Reference'!C65 | C32: =IFERROR(B32/'Filing Cross-Reference'!L65,0) | D32: =IF(B32>=20,"STRONG",IF(B32>=10,"ADEQUATE","WEAK"))
A33: MSC Super | B33: ='Filing Cross-Reference'!D65 | C33: =IFERROR(B33/'Filing Cross-Reference'!L65,0) | D33: =IF(B33>=20,"STRONG",IF(B33>=10,"ADEQUATE","WEAK"))
A34: Contempt | B34: ='Filing Cross-Reference'!E65 | C34: =IFERROR(B34/'Filing Cross-Reference'!L65,0) | D34: =IF(B34>=20,"STRONG",IF(B34>=10,"ADEQUATE","WEAK"))
A35: Disqual | B35: ='Filing Cross-Reference'!F65 | C35: =IFERROR(B35/'Filing Cross-Reference'!L65,0) | D35: =IF(B35>=20,"STRONG",IF(B35>=10,"ADEQUATE","WEAK"))
A36: Emergency PT | B36: ='Filing Cross-Reference'!G65 | C36: =IFERROR(B36/'Filing Cross-Reference'!L65,0) | D36: =IF(B36>=20,"STRONG",IF(B36>=10,"ADEQUATE","WEAK"))
A37: COA Brief | B37: ='Filing Cross-Reference'!H65 | C37: =IFERROR(B37/'Filing Cross-Reference'!L65,0) | D37: =IF(B37>=20,"STRONG",IF(B37>=10,"ADEQUATE","WEAK"))
A38: Housing | B38: ='Filing Cross-Reference'!I65 | C38: =IFERROR(B38/'Filing Cross-Reference'!L65,0) | D38: =IF(B38>=20,"STRONG",IF(B38>=10,"ADEQUATE","WEAK"))
A39: Federal | B39: ='Filing Cross-Reference'!J65 | C39: =IFERROR(B39/'Filing Cross-Reference'!L65,0) | D39: =IF(B39>=20,"STRONG",IF(B39>=10,"ADEQUATE","WEAK"))
A40: Tort | B40: ='Filing Cross-Reference'!K65 | C40: =IFERROR(B40/'Filing Cross-Reference'!L65,0) | D40: =IF(B40>=20,"STRONG",IF(B40>=10,"ADEQUATE","WEAK"))
A43: SECTION D: Lane Coverage Heatmap Data
A44: Lane | B44: Authority Count | C44: Avg Weight | D44: Chain Complete % | E44: Coverage Score | F44: Rating
A45: Lane A — Custody (Watson) | B45: ='Lane Assignment Matrix'!C65 | C45: =IFERROR(AVERAGEIF('Authority Index'!G$5:G$64,"*A*",'Authority Index'!I$5:I$64),0) | D45: ='Authority Chain Completeness'!C38 | E45: =IFERROR((B45*C45)/100,0) | F45: =IF(E45>=15,"EXCELLENT",IF(E45>=8,"GOOD",IF(E45>=3,"FAIR","WEAK")))
A46: Lane B — Housing (Shady Oaks) | B46: ='Lane Assignment Matrix'!D65 | C46: =IFERROR(AVERAGEIF('Authority Index'!G$5:G$64,"*B*",'Authority Index'!I$5:I$64),0) | D46: ='Authority Chain Completeness'!C38 | E46: =IFERROR((B46*C46)/100,0) | F46: =IF(E46>=15,"EXCELLENT",IF(E46>=8,"GOOD",IF(E46>=3,"FAIR","WEAK")))
A47: Lane C — Convergence | B47: ='Lane Assignment Matrix'!E65 | C47: =IFERROR(AVERAGEIF('Authority Index'!G$5:G$64,"*C*",'Authority Index'!I$5:I$64),0) | D47: ='Authority Chain Completeness'!C38 | E47: =IFERROR((B47*C47)/100,0) | F47: =IF(E47>=15,"EXCELLENT",IF(E47>=8,"GOOD",IF(E47>=3,"FAIR","WEAK")))
...
